INFO     [2024-02-29 15:05:42] Task: sample_task started at 2024-02-29 15:05:42
ERROR    [2024-02-29 15:13:56] [src.Task.load_task_template]: Error loading task template, please make sure the file <sample_task111.yaml> exists inside </Users/tongrao/Desktop/project/DataDoorkeeper/v1/templates/tasks> and in the correct format, double check if the name is correct.
DEBUG    [2024-02-29 15:13:56] [src.Task.load_task_template]: [Errno 2] No such file or directory: '/Users/tongrao/Desktop/project/DataDoorkeeper/v1/templates/tasks/sample_task111.yaml'
**********
Traceback (most recent call last):
  File "/Users/tongrao/Desktop/project/DataDoorkeeper/v1/src/Task.py", line 49, in load_task_template
    with open(path, 'r') as file:
FileNotFoundError: [Errno 2] No such file or directory: '/Users/tongrao/Desktop/project/DataDoorkeeper/v1/templates/tasks/sample_task111.yaml'
**********
INFO     [2024-02-29 15:16:24] [src.Task.load_task_template]: Loading task template <sample_task111.yaml>
ERROR    [2024-02-29 15:16:24] [src.Task.load_task_template]: Error loading task template, please make sure the file <sample_task111.yaml> exists inside </Users/tongrao/Desktop/project/DataDoorkeeper/v1/templates/tasks> and in the correct format, double check if the name is correct.
DEBUG    [2024-02-29 15:16:24] [src.Task.load_task_template]: [Errno 2] No such file or directory: '/Users/tongrao/Desktop/project/DataDoorkeeper/v1/templates/tasks/sample_task111.yaml'
**********
Traceback (most recent call last):
  File "/Users/tongrao/Desktop/project/DataDoorkeeper/v1/src/Task.py", line 50, in load_task_template
    with open(path, 'r') as file:
FileNotFoundError: [Errno 2] No such file or directory: '/Users/tongrao/Desktop/project/DataDoorkeeper/v1/templates/tasks/sample_task111.yaml'
**********
INFO     [2024-02-29 15:16:58] [src.Task.load_task_template]: Loading task template <sample_task111.yaml>
ERROR    [2024-02-29 15:16:58] [src.Task.load_task_template]: Error loading task template, please make sure the file <sample_task111.yaml> exists inside </Users/tongrao/Desktop/project/DataDoorkeeper/v1/templates/tasks> and in the correct format, double check if the name is correct, the task name has to be the same as the template file name.
DEBUG    [2024-02-29 15:16:58] [src.Task.load_task_template]: [Errno 2] No such file or directory: '/Users/tongrao/Desktop/project/DataDoorkeeper/v1/templates/tasks/sample_task111.yaml'
**********
Traceback (most recent call last):
  File "/Users/tongrao/Desktop/project/DataDoorkeeper/v1/src/Task.py", line 50, in load_task_template
    with open(path, 'r') as file:
FileNotFoundError: [Errno 2] No such file or directory: '/Users/tongrao/Desktop/project/DataDoorkeeper/v1/templates/tasks/sample_task111.yaml'
**********
INFO     [2024-02-29 15:17:56] [src.Task.load_task_template]: Loading task template <sample_task.yaml>
INFO     [2024-02-29 15:17:56] Task: sample_task started at 2024-02-29 15:17:56
INFO     [2024-02-29 15:18:28] [src.Task.load_task_template]: Loading task template <sample_task.yaml>
INFO     [2024-02-29 15:21:16] [src.Task.load_task_template]: Loading task template <sample_task.yaml>
INFO     [2024-02-29 15:23:04] [src.Task.load_task_template]: Loading task template <sample_task.yaml>
INFO     [2024-02-29 15:23:04] [src.Task.prepare_datasets]: Preparing datasets for task <sample_task>, there are total <3> templates.
INFO     [2024-02-29 15:23:27] [src.Task.load_task_template]: Loading task template <sample_task.yaml>
INFO     [2024-02-29 15:23:27] [src.Task.prepare_datasets]: Preparing datasets for task <sample_task>, found <3> templates.
INFO     [2024-02-29 15:24:16] [src.Task.load_task_template]: Loading task template <sample_task.yaml>
INFO     [2024-02-29 15:24:16] [src.Task.prepare_datasets]: Preparing datasets for task <sample_task>, found <3> templates.
INFO     [2024-02-29 15:24:16] [src.Task.prepare_datasets]: Preparing dataset <sample_dataset_01>, found <3> data files.
INFO     [2024-02-29 15:24:16] [src.Task.prepare_datasets]: Preparing dataset <sample_dataset_02>, found <3> data files.
INFO     [2024-02-29 15:24:16] [src.Task.prepare_datasets]: Preparing dataset <sample_dataset_03>, found <3> data files.
INFO     [2024-02-29 15:24:21] [src.Task.load_task_template]: Loading task template <sample_task.yaml>
INFO     [2024-02-29 15:24:21] [src.Task.prepare_datasets]: Preparing datasets for task <sample_task>, found <3> templates.
INFO     [2024-02-29 15:24:21] [src.Task.prepare_datasets]: Preparing dataset <sample_dataset_01>, found <3> data files.
INFO     [2024-02-29 15:24:21] [src.Task.prepare_datasets]: Preparing dataset <sample_dataset_02>, found <3> data files.
INFO     [2024-02-29 15:24:21] [src.Task.prepare_datasets]: Preparing dataset <sample_dataset_03>, found <3> data files.
INFO     [2024-02-29 15:24:38] [src.Task.load_task_template]: Loading task template <sample_task.yaml>
INFO     [2024-02-29 15:24:38] [src.Task.prepare_datasets]: Preparing datasets for task <sample_task>, found <3> templates.
INFO     [2024-02-29 15:24:38] [src.Task.prepare_datasets]: Preparing dataset <sample_dataset_01>, found <3> data files.
INFO     [2024-02-29 15:24:38] [src.Task.prepare_datasets]: Preparing dataset <sample_dataset_02>, found <2> data files.
INFO     [2024-02-29 15:24:38] [src.Task.prepare_datasets]: Preparing dataset <sample_dataset_03>, found <1> data files.
INFO     [2024-02-29 15:25:21] [src.Task.load_task_template]: Loading task template <sample_task.yaml>
INFO     [2024-02-29 15:25:21] [src.Task.prepare_datasets]: Preparing data for task <sample_task>, found <3> templates.
INFO     [2024-02-29 15:25:21] [src.Task.prepare_datasets]: Preparing template <sample_dataset_01>, found <3> data files related.
INFO     [2024-02-29 15:25:21] [src.Task.prepare_datasets]: Preparing template <sample_dataset_02>, found <2> data files related.
INFO     [2024-02-29 15:25:21] [src.Task.prepare_datasets]: Preparing template <sample_dataset_03>, found <1> data files related.
INFO     [2024-02-29 15:30:58] [src.Task.load_task_template]: Loading task template <sample_task1111.yaml>
ERROR    [2024-02-29 15:30:58] [src.Task.load_task_template]: Error loading task template, please make sure the file <sample_task1111.yaml> exists inside </Users/tongrao/Desktop/project/DataDoorkeeper/v1/templates/tasks> and in the correct format, double check if the name is correct, the task name has to be the same as the template file name.
DEBUG    [2024-02-29 15:30:58] [src.Task.load_task_template]: [Errno 2] No such file or directory: '/Users/tongrao/Desktop/project/DataDoorkeeper/v1/templates/tasks/sample_task1111.yaml'
**********
Traceback (most recent call last):
  File "/Users/tongrao/Desktop/project/DataDoorkeeper/v1/src/Task.py", line 62, in load_task_template
    with open(path, 'r') as file:
FileNotFoundError: [Errno 2] No such file or directory: '/Users/tongrao/Desktop/project/DataDoorkeeper/v1/templates/tasks/sample_task1111.yaml'
**********
INFO     [2024-02-29 15:32:30] [src.Task.load_task_template]: Loading task template <sample_task1111.yaml>
ERROR    [2024-02-29 15:32:30] [src.Task.load_task_template]: Error loading task template, please make sure the file <sample_task1111.yaml> exists inside </Users/tongrao/Desktop/project/DataDoorkeeper/v1/templates/tasks> and in the correct format, double check if the name is correct, the task name has to be the same as the template file name.
DEBUG    [2024-02-29 15:32:30] [src.Task.load_task_template]: [Errno 2] No such file or directory: '/Users/tongrao/Desktop/project/DataDoorkeeper/v1/templates/tasks/sample_task1111.yaml'
**********
Traceback (most recent call last):
  File "/Users/tongrao/Desktop/project/DataDoorkeeper/v1/src/Task.py", line 62, in load_task_template
    with open(path, 'r') as file:
FileNotFoundError: [Errno 2] No such file or directory: '/Users/tongrao/Desktop/project/DataDoorkeeper/v1/templates/tasks/sample_task1111.yaml'
**********
INFO     [2024-02-29 15:32:35] [src.Task.load_task_template]: Loading task template <sample_task1111.yaml>
ERROR    [2024-02-29 15:32:35] [src.Task.load_task_template]: Error loading task template, please make sure the file <sample_task1111.yaml> exists inside </Users/tongrao/Desktop/project/DataDoorkeeper/v1/templates/tasks> and in the correct format, double check if the name is correct, the task name has to be the same as the template file name.
DEBUG    [2024-02-29 15:32:35] [src.Task.load_task_template]: [Errno 2] No such file or directory: '/Users/tongrao/Desktop/project/DataDoorkeeper/v1/templates/tasks/sample_task1111.yaml'
**********
Traceback (most recent call last):
  File "/Users/tongrao/Desktop/project/DataDoorkeeper/v1/src/Task.py", line 62, in load_task_template
    with open(path, 'r') as file:
FileNotFoundError: [Errno 2] No such file or directory: '/Users/tongrao/Desktop/project/DataDoorkeeper/v1/templates/tasks/sample_task1111.yaml'
**********
ERROR    [2024-02-29 15:32:35] [src.Task.load_task_template]: Critical error found, ending the program.
INFO     [2024-02-29 15:33:01] [src.Task.load_task_template]: Loading task template <sample_task1111.yaml>
ERROR    [2024-02-29 15:33:01] [src.Task.load_task_template]: Error loading task template, please make sure the file <sample_task1111.yaml> exists inside </Users/tongrao/Desktop/project/DataDoorkeeper/v1/templates/tasks> and in the correct format, double check if the name is correct, the task name has to be the same as the template file name.
DEBUG    [2024-02-29 15:33:01] [src.Task.load_task_template]: [Errno 2] No such file or directory: '/Users/tongrao/Desktop/project/DataDoorkeeper/v1/templates/tasks/sample_task1111.yaml'
**********
Traceback (most recent call last):
  File "/Users/tongrao/Desktop/project/DataDoorkeeper/v1/src/Task.py", line 62, in load_task_template
    with open(path, 'r') as file:
FileNotFoundError: [Errno 2] No such file or directory: '/Users/tongrao/Desktop/project/DataDoorkeeper/v1/templates/tasks/sample_task1111.yaml'
**********
ERROR    [2024-02-29 15:33:01] [src.Task.load_task_template]: Critical error found, ending the program.
INFO     [2024-02-29 15:34:43] [src.Task.load_task_template]: Loading task template <sample_task1111.yaml>
ERROR    [2024-02-29 15:34:43] [src.Task.load_task_template]: Failed loading task template, please make sure the file <sample_task1111.yaml> exists inside </Users/tongrao/Desktop/project/DataDoorkeeper/v1/templates/tasks> and in the correct format, double check if the name is correct, the task name has to be the same as the template file name.
DEBUG    [2024-02-29 15:34:43] [src.Task.load_task_template]: [Errno 2] No such file or directory: '/Users/tongrao/Desktop/project/DataDoorkeeper/v1/templates/tasks/sample_task1111.yaml'
**********
Traceback (most recent call last):
  File "/Users/tongrao/Desktop/project/DataDoorkeeper/v1/src/Task.py", line 62, in load_task_template
    with open(path, 'r') as file:
FileNotFoundError: [Errno 2] No such file or directory: '/Users/tongrao/Desktop/project/DataDoorkeeper/v1/templates/tasks/sample_task1111.yaml'
**********
ERROR    [2024-02-29 15:34:43] [src.Task.load_task_template]: Critical error found, ending the program.
INFO     [2024-02-29 15:35:25] --------------------------------------------------
INFO     [2024-02-29 15:35:25] [src.Task.load_task_template]: Loading task template <sample_task1111.yaml>
ERROR    [2024-02-29 15:35:25] [src.Task.load_task_template]: Failed loading task template, please make sure the file <sample_task1111.yaml> exists inside </Users/tongrao/Desktop/project/DataDoorkeeper/v1/templates/tasks> and in the correct format, double check if the name is correct, the task name has to be the same as the template file name.
DEBUG    [2024-02-29 15:35:25] [src.Task.load_task_template]: [Errno 2] No such file or directory: '/Users/tongrao/Desktop/project/DataDoorkeeper/v1/templates/tasks/sample_task1111.yaml'
**********
Traceback (most recent call last):
  File "/Users/tongrao/Desktop/project/DataDoorkeeper/v1/src/Task.py", line 63, in load_task_template
    with open(path, 'r') as file:
FileNotFoundError: [Errno 2] No such file or directory: '/Users/tongrao/Desktop/project/DataDoorkeeper/v1/templates/tasks/sample_task1111.yaml'
**********
ERROR    [2024-02-29 15:35:25] [src.Task.load_task_template]: Critical error found, ending the program.
INFO     [2024-02-29 15:35:43] ----------------------------------------------------------------------------------------------------
INFO     [2024-02-29 15:35:43] [src.Task.load_task_template]: Loading task template <sample_task1111.yaml>
ERROR    [2024-02-29 15:35:43] [src.Task.load_task_template]: Failed loading task template, please make sure the file <sample_task1111.yaml> exists inside </Users/tongrao/Desktop/project/DataDoorkeeper/v1/templates/tasks> and in the correct format, double check if the name is correct, the task name has to be the same as the template file name.
DEBUG    [2024-02-29 15:35:43] [src.Task.load_task_template]: [Errno 2] No such file or directory: '/Users/tongrao/Desktop/project/DataDoorkeeper/v1/templates/tasks/sample_task1111.yaml'
**********
Traceback (most recent call last):
  File "/Users/tongrao/Desktop/project/DataDoorkeeper/v1/src/Task.py", line 63, in load_task_template
    with open(path, 'r') as file:
FileNotFoundError: [Errno 2] No such file or directory: '/Users/tongrao/Desktop/project/DataDoorkeeper/v1/templates/tasks/sample_task1111.yaml'
**********
ERROR    [2024-02-29 15:35:43] [src.Task.load_task_template]: Critical error found, ending the program.
INFO     [2024-02-29 15:36:50] ----------------------------------------------------------------------------------------------------
INFO     [2024-02-29 15:36:50] [src.Task.load_task_template]: Loading task template <sample_task.yaml>
INFO     [2024-02-29 15:36:50] [src.Task.prepare_datasets]: Preparing data for task <sample_task>, found <3> templates.
INFO     [2024-02-29 15:36:50] [src.Task.prepare_datasets]: Preparing template <sample_dataset_01>, found <3> data files related.
INFO     [2024-02-29 15:36:50] [src.Task.prepare_datasets]: Preparing template <sample_dataset_02>, found <2> data files related.
INFO     [2024-02-29 15:36:50] [src.Task.prepare_datasets]: Preparing template <sample_dataset_03>, found <1> data files related.
INFO     [2024-02-29 15:47:02] ----------------------------------------------------------------------------------------------------
INFO     [2024-02-29 15:47:02] [src.Task.load_task_template]: Loading task template <sample_task.yaml>
INFO     [2024-02-29 15:47:02] [src.Task.prepare_datasets]: Checking data for task <sample_task>, found <3> templates.
ERROR    [2024-02-29 15:47:02] [src.Task.prepare_datasets]: 
DEBUG    [2024-02-29 15:47:02] [src.Task.prepare_datasets]: 'Task' object has no attribute 'check_dataset_validation'
**********
Traceback (most recent call last):
  File "/Users/tongrao/Desktop/project/DataDoorkeeper/v1/src/Task.py", line 81, in prepare_datasets
    self.check_dataset_validation(dataset, self.task_yaml["datasets"][dataset])
AttributeError: 'Task' object has no attribute 'check_dataset_validation'
**********
ERROR    [2024-02-29 15:47:02] [src.Task.prepare_datasets]: Critical error found, ending the program.

INFO     [2024-02-29 15:49:11] ----------------------------------------------------------------------------------------------------
INFO     [2024-02-29 15:49:11] [src.Task.load_task_template]: Loading task template <sample_task.yaml>
INFO     [2024-02-29 15:49:11] [src.Task.prepare_datasets]: Checking data for task <sample_task>, found <3> templates.
ERROR    [2024-02-29 15:49:11] [src.Task.prepare_datasets]: 
DEBUG    [2024-02-29 15:49:11] [src.Task.prepare_datasets]: 'Task' object has no attribute 'check_dataset_validation'
**********
Traceback (most recent call last):
  File "/Users/tongrao/Desktop/project/DataDoorkeeper/v1/src/Task.py", line 82, in prepare_datasets
    self.check_dataset_validation(dataset, self.task_yaml["datasets"][dataset])
AttributeError: 'Task' object has no attribute 'check_dataset_validation'
**********
ERROR    [2024-02-29 15:49:11] [src.Task.prepare_datasets]: Critical error found, ending the program.

INFO     [2024-02-29 15:49:37] ----------------------------------------------------------------------------------------------------
INFO     [2024-02-29 15:49:37] [src.Task.load_task_template]: Loading task template <sample_task.yaml>
INFO     [2024-02-29 15:49:37] [src.Task.prepare_datasets]: Checking data for task <sample_task>, found <3> templates.
ERROR    [2024-02-29 15:49:37] [src.Task.prepare_datasets]: 
DEBUG    [2024-02-29 15:49:37] [src.Task.prepare_datasets]: 'Task' object has no attribute 'check_dataset_validation'
**********
Traceback (most recent call last):
  File "/Users/tongrao/Desktop/project/DataDoorkeeper/v1/src/Task.py", line 83, in prepare_datasets
    self.check_dataset_validation(dataset, self.task_yaml["datasets"][dataset])
AttributeError: 'Task' object has no attribute 'check_dataset_validation'
**********
ERROR    [2024-02-29 15:49:37] [src.Task.prepare_datasets]: Critical error found, ending the program.

INFO     [2024-02-29 15:57:49] ----------------------------------------------------------------------------------------------------
INFO     [2024-02-29 15:57:49] [src.Task.load_task_template]: Loading task template <sample_task.yaml>
INFO     [2024-02-29 15:57:49] [src.Task.prepare_datasets]: Checking data for task <sample_task>, found <3> templates.
ERROR    [2024-02-29 15:57:49] [src.Task.prepare_datasets]: something went wrong while checking the dataset <sample_dataset_01>
DEBUG    [2024-02-29 15:57:49] [src.Task.prepare_datasets]: 'Task' object has no attribute 'check_dataset_validation'
**********
Traceback (most recent call last):
  File "/Users/tongrao/Desktop/project/DataDoorkeeper/v1/src/Task.py", line 81, in prepare_datasets
    self.check_dataset_validation(dataset, self.task_yaml["datasets"][dataset])
AttributeError: 'Task' object has no attribute 'check_dataset_validation'
**********
ERROR    [2024-02-29 15:57:49] [src.Task.prepare_datasets]: Critical error found, ending the program.
something went wrong while checking the dataset <sample_dataset_01>
INFO     [2024-02-29 15:58:27] ----------------------------------------------------------------------------------------------------
INFO     [2024-02-29 15:58:27] [src.Task.load_task_template]: Loading task template <sample_task.yaml>
INFO     [2024-02-29 15:58:27] [src.Task.prepare_datasets]: Checking data for task <sample_task>, found <3> templates.
ERROR    [2024-02-29 15:58:27] [src.Task.prepare_datasets]: something went wrong while checking the dataset <sample_dataset_01>
DEBUG    [2024-02-29 15:58:27] [src.Task.prepare_datasets]: 'Task' object has no attribute 'check_dataset_validation'
**********
Traceback (most recent call last):
  File "/Users/tongrao/Desktop/project/DataDoorkeeper/v1/src/Task.py", line 81, in prepare_datasets
    self.check_dataset_validation(dataset, self.task_yaml["datasets"][dataset])
AttributeError: 'Task' object has no attribute 'check_dataset_validation'
**********
ERROR    [2024-02-29 15:58:27] [src.Task.prepare_datasets]: Critical error found, ending the program.
INFO     [2024-02-29 16:02:16] ----------------------------------------------------------------------------------------------------
INFO     [2024-02-29 16:02:16] [src.Task.load_task_template]: Loading task template <sample_task.yaml>
INFO     [2024-02-29 16:02:16] [src.Task.prepare_datasets]: Checking data for task <sample_task>, found <3> templates.
ERROR    [2024-02-29 16:02:16] [src.Task.prepare_datasets]: something went wrong while checking the dataset <sample_dataset_01>
DEBUG    [2024-02-29 16:02:16] [src.Task.prepare_datasets]: 'Task' object has no attribute 'check_dataset_validation'
**********
Traceback (most recent call last):
  File "/Users/tongrao/Desktop/project/DataDoorkeeper/v1/src/Task.py", line 81, in prepare_datasets
    self.check_dataset_validation(dataset, self.task_yaml["datasets"][dataset])
AttributeError: 'Task' object has no attribute 'check_dataset_validation'
**********
ERROR    [2024-02-29 16:02:16] [src.Task.prepare_datasets]: Critical error found, ending the program.
INFO     [2024-02-29 16:03:30] ----------------------------------------------------------------------------------------------------
INFO     [2024-02-29 16:03:30] [src.Task.load_task_template]: Loading task template <sample_task.yaml>
INFO     [2024-02-29 16:03:30] [src.Task.prepare_datasets]: Checking data for task <sample_task>, found <3> templates.
ERROR    [2024-02-29 16:03:30] [src.Task.prepare_datasets]: something went wrong while checking the dataset <sample_dataset_01>
DEBUG    [2024-02-29 16:03:30] [src.Task.prepare_datasets]: 'Task' object has no attribute 'check_dataset_validation'
**********
Traceback (most recent call last):
  File "/Users/tongrao/Desktop/project/DataDoorkeeper/v1/src/Task.py", line 81, in prepare_datasets
    self.check_dataset_validation(dataset, self.task_yaml["datasets"][dataset])
AttributeError: 'Task' object has no attribute 'check_dataset_validation'
**********
ERROR    [2024-02-29 16:03:30] [src.Task.prepare_datasets]: Critical error found, ending the program.
INFO     [2024-02-29 16:04:35] ----------------------------------------------------------------------------------------------------
INFO     [2024-02-29 16:04:35] [src.Task.load_task_template]: Loading task template <sample_task.yaml>
INFO     [2024-02-29 16:04:35] [src.Task.prepare_datasets]: Checking data for task <sample_task>, found <3> templates.
INFO     [2024-02-29 16:04:35] [src.Task.prepare_datasets]: Successfully loaded dataset <sample_dataset_01>
INFO     [2024-02-29 16:04:35] [src.Task.prepare_datasets]: Checking template <sample_dataset_01>, found <3> data files related.
INFO     [2024-02-29 16:04:35] [src.Task.prepare_datasets]: Successfully loaded dataset <sample_dataset_02>
INFO     [2024-02-29 16:04:35] [src.Task.prepare_datasets]: Checking template <sample_dataset_02>, found <2> data files related.
INFO     [2024-02-29 16:04:35] [src.Task.prepare_datasets]: Successfully loaded dataset <sample_dataset_03>
INFO     [2024-02-29 16:04:35] [src.Task.prepare_datasets]: Checking template <sample_dataset_03>, found <1> data files related.
INFO     [2024-02-29 16:05:14] ----------------------------------------------------------------------------------------------------
INFO     [2024-02-29 16:05:14] [src.Task.load_task_template]: Loading task template <sample_task.yaml>
INFO     [2024-02-29 16:05:14] [src.Task.prepare_datasets]: Checking data for task <sample_task>, found <3> templates.
INFO     [2024-02-29 16:05:14] [src.Task.prepare_datasets]: Successfully checked template <sample_dataset_01>, found <3> data files related.
INFO     [2024-02-29 16:05:14] [src.Task.prepare_datasets]: Successfully checked template <sample_dataset_02>, found <2> data files related.
INFO     [2024-02-29 16:05:14] [src.Task.prepare_datasets]: Successfully checked template <sample_dataset_03>, found <1> data files related.
INFO     [2024-02-29 16:05:41] ----------------------------------------------------------------------------------------------------
INFO     [2024-02-29 16:05:41] [src.Task.load_task_template]: Loading task template <sample_task.yaml>
INFO     [2024-02-29 16:05:41] [src.Task.prepare_datasets]: Checking data for task <sample_task>, found <3> templates.
INFO     [2024-02-29 16:05:41] [src.Task.prepare_datasets]: Successfully checked template <sample_dataset_01>, <3> files passed.
INFO     [2024-02-29 16:05:41] [src.Task.prepare_datasets]: Successfully checked template <sample_dataset_02>, <2> files passed.
INFO     [2024-02-29 16:05:41] [src.Task.prepare_datasets]: Successfully checked template <sample_dataset_03>, <1> files passed.
INFO     [2024-02-29 16:09:01] ----------------------------------------------------------------------------------------------------
INFO     [2024-02-29 16:09:01] [src.Task.load_task_template]: Loading task template <sample_task.yaml>
INFO     [2024-02-29 16:09:01] [src.Task.prepare_datasets]: Checking data for task <sample_task>, found <3> templates.
INFO     [2024-02-29 16:09:01] [src.Task.prepare_datasets]: Successfully checked template <sample_dataset_01>, <3> files passed.
INFO     [2024-02-29 16:09:01] [src.Task.prepare_datasets]: Successfully checked template <sample_dataset_02>, <2> files passed.
INFO     [2024-02-29 16:09:01] [src.Task.prepare_datasets]: Successfully checked template <sample_dataset_03>, <1> files passed.
ERROR    [2024-02-29 16:09:01] [src.Task.prepare_datasets]: Critical error found, ending the program.
INFO     [2024-06-03 14:05:35] test
INFO     [2024-06-03 14:08:40] test
INFO     [2024-06-03 14:14:00] test
INFO     [2024-06-03 14:14:52] test
INFO     [2024-06-03 16:09:03] Data is valid!
INFO     [2024-06-03 16:12:49] [_validate_data]: Data is valid!
